Workbook
Name lst_cadencia: OFFSET(Listas!$C$3,0,0,MAX(1,COUNTA(Listas!$C$3:$C$100)),1)
Name lst_evento: OFFSET(Listas!$G$3,0,0,MAX(1,COUNTA(Listas!$G$3:$G$100)),1)
Name lst_fase: OFFSET(Listas!$A$3,0,0,MAX(1,COUNTA(Listas!$A$3:$A$100)),1)
Name lst_mobilizacao: OFFSET(Listas!$D$3,0,0,MAX(1,COUNTA(Listas!$D$3:$D$100)),1)
Name lst_obras: OFFSET(Carteira!$A$5,0,0,MAX(1,COUNTA(Carteira!$A$5:$A$204)),1)
Name lst_origem: OFFSET(Listas!$F$3,0,0,MAX(1,COUNTA(Listas!$F$3:$F$100)),1)
Name lst_pm: OFFSET(Listas!$H$3,0,0,MAX(1,COUNTA(Listas!$H$3:$H$100)),1)
Name lst_situacao: OFFSET(Listas!$B$3,0,0,MAX(1,COUNTA(Listas!$B$3:$B$100)),1)
Name lst_status: OFFSET(Listas!$E$3,0,0,MAX(1,COUNTA(Listas!$E$3:$E$100)),1)
Name par_alerta_dias: Listas!$K$3
Name par_critico_dias: Listas!$K$4
Name par_mob_alerta: Listas!$K$5
Name par_mob_critico: Listas!$K$6

Sheet Painel
F2: GERENCIAMENTO DA COORDENAÇÃO DE PLANEJAMENTO | N2: Data de referência
F3: Departamento de Instalação · Acompanhamento da carteira de obras | N3: =TODAY() -> 46302
N4: Coordenação: Arthur Felipe Furtuoso Araujo
B7: 1 · INDICADORES DA CARTEIRA
B8: Calculados automaticamente a partir da aba Carteira
B9: Obras na carteira | D9: No prazo | F9: Atenção | H9: Bloqueado | J9: Cronogramas validados | L9: Com reunião recorrente | N9: Sem interação
B10: =COUNTA(Carteira!$A$5:$A$204) -> 12 | D10: =COUNTIF(Carteira!$N$5:$N$204,"No prazo") -> 8 | F10: =COUNTIF(Carteira!$N$5:$N$204,"Atenção") -> 2 | H10: =COUNTIF(Carteira!$N$5:$N$204,"Bloqueado") -> 1 | J10: =COUNTIF(Carteira!$F$5:$F$204,"Validado*") -> 4 | L10: =SUMPRODUCT((Carteira!$G$5:$G$204<>"")*(Carteira!$G$5:$G$204<>"Sem recorrência definida")*(Carteira!$G$5:$G$204<>"Não informada")) -> 1 | N10: =COUNTIF(Carteira!$M$5:$M$204,">"&par_alerta_dias) -> 7
B11: ="obras ativas" -> obras ativas | D11: =IF($B$10=0,"",TEXT(D10/$B$10,"0%")&" da carteira") -> 67% da carteira | F11: =IF($B$10=0,"",TEXT(F10/$B$10,"0%")&" da carteira") -> 17% da carteira | H11: =IF($B$10=0,"",TEXT(H10/$B$10,"0%")&" da carteira") -> 8% da carteira | J11: =IF($B$10=0,"",TEXT(J10/$B$10,"0%")&" da carteira") -> 33% da carteira | L11: =IF($B$10=0,"",TEXT(L10/$B$10,"0%")&" da carteira") -> 8% da carteira | N11: ="há mais de "&par_alerta_dias&" dias" -> há mais de 7 dias
B13: 2 · FLUXO DO CRONOGRAMA — EM QUE ETAPA ESTÁ CADA OBRA
B14: Da elaboração à atualização periódica · as etapas e seus nomes vêm da aba Listas (coluna 'Situação do cronograma')
B15: ETAPA 1 | C15: → | D15: ETAPA 2 | E15: → | F15: ETAPA 3 | G15: → | H15: ETAPA 4 | I15: → | J15: ETAPA 5 | K15: → | L15: ETAPA 6 | M15: ┆ | N15: SEM INFORMAÇÃO
B16: =Listas!$B$3 -> Em elaboração | D16: =Listas!$B$4 -> Estruturado – aguardando validação | F16: =Listas!$B$5 -> Em ajuste com o PM | H16: =Listas!$B$6 -> Validado pelo PM | J16: =Listas!$B$7 -> Validado e entregue | L16: =Listas!$B$8 -> Em atualização periódica | N16: =Listas!$B$9 -> Não informada
B17: =COUNTIF(Carteira!$F$5:$F$204,Listas!$B$3) -> 0 | D17: =COUNTIF(Carteira!$F$5:$F$204,Listas!$B$4) -> 2 | F17: =COUNTIF(Carteira!$F$5:$F$204,Listas!$B$5) -> 1 | H17: =COUNTIF(Carteira!$F$5:$F$204,Listas!$B$6) -> 1 | J17: =COUNTIF(Carteira!$F$5:$F$204,Listas!$B$7) -> 3 | L17: =COUNTIF(Carteira!$F$5:$F$204,Listas!$B$8) -> 5 | N17: =COUNTIF(Carteira!$F$5:$F$204,Listas!$B$9) -> 0
B18: =IF(B17=1,"obra","obras") -> obras | D18: =IF(D17=1,"obra","obras") -> obras | F18: =IF(F17=1,"obra","obras") -> obra | H18: =IF(H17=1,"obra","obras") -> obra | J18: =IF(J17=1,"obra","obras") -> obras | L18: =IF(L17=1,"obra","obras") -> obras | N18: =IF(N17=1,"obra","obras") -> obras
B19: ↺ Após a entrega, o cronograma entra no ciclo de atualização periódica e retorna à validação a cada revisão relevante. | N19: ="Total: "&SUM(B17,D17,F17,H17,J17,L17,N17)&" obras" -> Total: 12 obras
B21: 3 · DISTRIBUIÇÃO POR PM
B22: Novos PMs cadastrados na aba Listas aparecem aqui automaticamente (até 10)
B23: PM | D23: Obras | F23: No prazo | H23: Atenção | J23: Bloqueado | L23: Aguardando validação | N23: Validados
B24: =IF(Listas!$H$3="","",Listas!$H$3) -> PAULO NETTO | D24: =IF($B24="","",COUNTIF(Carteira!$C$5:$C$204,$B24)) -> 2 | F24: =IF($B24="","",COUNTIFS(Carteira!$C$5:$C$204,$B24,Carteira!$N$5:$N$204,"No prazo")) -> 1 | H24: =IF($B24="","",COUNTIFS(Carteira!$C$5:$C$204,$B24,Carteira!$N$5:$N$204,"Atenção")) -> 0 | J24: =IF($B24="","",COUNTIFS(Carteira!$C$5:$C$204,$B24,Carteira!$N$5:$N$204,"Bloqueado")) -> 1 | L24: =IF($B24="","",COUNTIFS(Carteira!$C$5:$C$204,$B24,Carteira!$F$5:$F$204,Listas!$B$4)+COUNTIFS(Carteira!$C$5:$C$204,$B24,Carteira!$F$5:$F$204,Listas!$B$5)) -> 1 | N24: =IF($B24="","",COUNTIFS(Carteira!$C$5:$C$204,$B24,Carteira!$F$5:$F$204,"Validado*")) -> 1
B25: =IF(Listas!$H$4="","",Listas!$H$4) -> MATHEUS | D25: =IF($B25="","",COUNTIF(Carteira!$C$5:$C$204,$B25)) -> 1 | F25: =IF($B25="","",COUNTIFS(Carteira!$C$5:$C$204,$B25,Carteira!$N$5:$N$204,"No prazo")) -> 0 | H25: =IF($B25="","",COUNTIFS(Carteira!$C$5:$C$204,$B25,Carteira!$N$5:$N$204,"Atenção")) -> 1 | J25: =IF($B25="","",COUNTIFS(Carteira!$C$5:$C$204,$B25,Carteira!$N$5:$N$204,"Bloqueado")) -> 0 | L25: =IF($B25="","",COUNTIFS(Carteira!$C$5:$C$204,$B25,Carteira!$F$5:$F$204,Listas!$B$4)+COUNTIFS(Carteira!$C$5:$C$204,$B25,Carteira!$F$5:$F$204,Listas!$B$5)) -> 1 | N25: =IF($B25="","",COUNTIFS(Carteira!$C$5:$C$204,$B25,Carteira!$F$5:$F$204,"Validado*")) -> 0
B26: =IF(Listas!$H$5="","",Listas!$H$5) -> JEOVANNA | D26: =IF($B26="","",COUNTIF(Carteira!$C$5:$C$204,$B26)) -> 2 | F26: =IF($B26="","",COUNTIFS(Carteira!$C$5:$C$204,$B26,Carteira!$N$5:$N$204,"No prazo")) -> 1 | H26: =IF($B26="","",COUNTIFS(Carteira!$C$5:$C$204,$B26,Carteira!$N$5:$N$204,"Atenção")) -> 1 | J26: =IF($B26="","",COUNTIFS(Carteira!$C$5:$C$204,$B26,Carteira!$N$5:$N$204,"Bloqueado")) -> 0 | L26: =IF($B26="","",COUNTIFS(Carteira!$C$5:$C$204,$B26,Carteira!$F$5:$F$204,Listas!$B$4)+COUNTIFS(Carteira!$C$5:$C$204,$B26,Carteira!$F$5:$F$204,Listas!$B$5)) -> 1 | N26: =IF($B26="","",COUNTIFS(Carteira!$C$5:$C$204,$B26,Carteira!$F$5:$F$204,"Validado*")) -> 0
B27: =IF(Listas!$H$6="","",Listas!$H$6) -> ERIKA | D27: =IF($B27="","",COUNTIF(Carteira!$C$5:$C$204,$B27)) -> 4 | F27: =IF($B27="","",COUNTIFS(Carteira!$C$5:$C$204,$B27,Carteira!$N$5:$N$204,"No prazo")) -> 4 | H27: =IF($B27="","",COUNTIFS(Carteira!$C$5:$C$204,$B27,Carteira!$N$5:$N$204,"Atenção")) -> 0 | J27: =IF($B27="","",COUNTIFS(Carteira!$C$5:$C$204,$B27,Carteira!$N$5:$N$204,"Bloqueado")) -> 0 | L27: =IF($B27="","",COUNTIFS(Carteira!$C$5:$C$204,$B27,Carteira!$F$5:$F$204,Listas!$B$4)+COUNTIFS(Carteira!$C$5:$C$204,$B27,Carteira!$F$5:$F$204,Listas!$B$5)) -> 0 | N27: =IF($B27="","",COUNTIFS(Carteira!$C$5:$C$204,$B27,Carteira!$F$5:$F$204,"Validado*")) -> 0
B28: =IF(Listas!$H$7="","",Listas!$H$7) -> LAERÇO | D28: =IF($B28="","",COUNTIF(Carteira!$C$5:$C$204,$B28)) -> 2 | F28: =IF($B28="","",COUNTIFS(Carteira!$C$5:$C$204,$B28,Carteira!$N$5:$N$204,"No prazo")) -> 2 | H28: =IF($B28="","",COUNTIFS(Carteira!$C$5:$C$204,$B28,Carteira!$N$5:$N$204,"Atenção")) -> 0 | J28: =IF($B28="","",COUNTIFS(Carteira!$C$5:$C$204,$B28,Carteira!$N$5:$N$204,"Bloqueado")) -> 0 | L28: =IF($B28="","",COUNTIFS(Carteira!$C$5:$C$204,$B28,Carteira!$F$5:$F$204,Listas!$B$4)+COUNTIFS(Carteira!$C$5:$C$204,$B28,Carteira!$F$5:$F$204,Listas!$B$5)) -> 0 | N28: =IF($B28="","",COUNTIFS(Carteira!$C$5:$C$204,$B28,Carteira!$F$5:$F$204,"Validado*")) -> 2
B29: =IF(Listas!$H$8="","",Listas!$H$8) -> LAURA | D29: =IF($B29="","",COUNTIF(Carteira!$C$5:$C$204,$B29)) -> 1 | F29: =IF($B29="","",COUNTIFS(Carteira!$C$5:$C$204,$B29,Carteira!$N$5:$N$204,"No prazo")) -> 0 | H29: =IF($B29="","",COUNTIFS(Carteira!$C$5:$C$204,$B29,Carteira!$N$5:$N$204,"Atenção")) -> 0 | J29: =IF($B29="","",COUNTIFS(Carteira!$C$5:$C$204,$B29,Carteira!$N$5:$N$204,"Bloqueado")) -> 0 | L29: =IF($B29="","",COUNTIFS(Carteira!$C$5:$C$204,$B29,Carteira!$F$5:$F$204,Listas!$B$4)+COUNTIFS(Carteira!$C$5:$C$204,$B29,Carteira!$F$5:$F$204,Listas!$B$5)) -> 0 | N29: =IF($B29="","",COUNTIFS(Carteira!$C$5:$C$204,$B29,Carteira!$F$5:$F$204,"Validado*")) -> 1
B30: =IF(Listas!$H$9="","",Listas!$H$9) | D30: =IF($B30="","",COUNTIF(Carteira!$C$5:$C$204,$B30)) | F30: =IF($B30="","",COUNTIFS(Carteira!$C$5:$C$204,$B30,Carteira!$N$5:$N$204,"No prazo")) | H30: =IF($B30="","",COUNTIFS(Carteira!$C$5:$C$204,$B30,Carteira!$N$5:$N$204,"Atenção")) | J30: =IF($B30="","",COUNTIFS(Carteira!$C$5:$C$204,$B30,Carteira!$N$5:$N$204,"Bloqueado")) | L30: =IF($B30="","",COUNTIFS(Carteira!$C$5:$C$204,$B30,Carteira!$F$5:$F$204,Listas!$B$4)+COUNTIFS(Carteira!$C$5:$C$204,$B30,Carteira!$F$5:$F$204,Listas!$B$5)) | N30: =IF($B30="","",COUNTIFS(Carteira!$C$5:$C$204,$B30,Carteira!$F$5:$F$204,"Validado*"))
B31: =IF(Listas!$H$10="","",Listas!$H$10) | D31: =IF($B31="","",COUNTIF(Carteira!$C$5:$C$204,$B31)) | F31: =IF($B31="","",COUNTIFS(Carteira!$C$5:$C$204,$B31,Carteira!$N$5:$N$204,"No prazo")) | H31: =IF($B31="","",COUNTIFS(Carteira!$C$5:$C$204,$B31,Carteira!$N$5:$N$204,"Atenção")) | J31: =IF($B31="","",COUNTIFS(Carteira!$C$5:$C$204,$B31,Carteira!$N$5:$N$204,"Bloqueado")) | L31: =IF($B31="","",COUNTIFS(Carteira!$C$5:$C$204,$B31,Carteira!$F$5:$F$204,Listas!$B$4)+COUNTIFS(Carteira!$C$5:$C$204,$B31,Carteira!$F$5:$F$204,Listas!$B$5)) | N31: =IF($B31="","",COUNTIFS(Carteira!$C$5:$C$204,$B31,Carteira!$F$5:$F$204,"Validado*"))
B32: =IF(Listas!$H$11="","",Listas!$H$11) | D32: =IF($B32="","",COUNTIF(Carteira!$C$5:$C$204,$B32)) | F32: =IF($B32="","",COUNTIFS(Carteira!$C$5:$C$204,$B32,Carteira!$N$5:$N$204,"No prazo")) | H32: =IF($B32="","",COUNTIFS(Carteira!$C$5:$C$204,$B32,Carteira!$N$5:$N$204,"Atenção")) | J32: =IF($B32="","",COUNTIFS(Carteira!$C$5:$C$204,$B32,Carteira!$N$5:$N$204,"Bloqueado")) | L32: =IF($B32="","",COUNTIFS(Carteira!$C$5:$C$204,$B32,Carteira!$F$5:$F$204,Listas!$B$4)+COUNTIFS(Carteira!$C$5:$C$204,$B32,Carteira!$F$5:$F$204,Listas!$B$5)) | N32: =IF($B32="","",COUNTIFS(Carteira!$C$5:$C$204,$B32,Carteira!$F$5:$F$204,"Validado*"))
B33: =IF(Listas!$H$12="","",Listas!$H$12) | D33: =IF($B33="","",COUNTIF(Carteira!$C$5:$C$204,$B33)) | F33: =IF($B33="","",COUNTIFS(Carteira!$C$5:$C$204,$B33,Carteira!$N$5:$N$204,"No prazo")) | H33: =IF($B33="","",COUNTIFS(Carteira!$C$5:$C$204,$B33,Carteira!$N$5:$N$204,"Atenção")) | J33: =IF($B33="","",COUNTIFS(Carteira!$C$5:$C$204,$B33,Carteira!$N$5:$N$204,"Bloqueado")) | L33: =IF($B33="","",COUNTIFS(Carteira!$C$5:$C$204,$B33,Carteira!$F$5:$F$204,Listas!$B$4)+COUNTIFS(Carteira!$C$5:$C$204,$B33,Carteira!$F$5:$F$204,Listas!$B$5)) | N33: =IF($B33="","",COUNTIFS(Carteira!$C$5:$C$204,$B33,Carteira!$F$5:$F$204,"Validado*"))
B34: TOTAL | D34: =SUM(D24:D33) -> 12 | F34: =SUM(F24:F33) -> 8 | H34: =SUM(H24:H33) -> 2 | J34: =SUM(J24:J33) -> 1 | L34: =SUM(L24:L33) -> 3 | N34: =SUM(N24:N33) -> 4
B36: 4 · PONTOS DE ATENÇÃO PARA A REUNIÃO
B37: Obras com status 'Bloqueado' (primeiro) e 'Atenção' · lista atualizada automaticamente (até 10)
B38: Nº da obra | C38: Cliente | E38: PM | G38: Status | I38: Dias sem interação | K38: Pendência / bloqueio
B39: =IFERROR(INDEX(Carteira!$A:$A,MOD(SMALL(Carteira!$Q$5:$Q$204,1),10000)),"") -> 24520001 | C39: =IFERROR(INDEX(Carteira!$B:$B,MOD(SMALL(Carteira!$Q$5:$Q$204,1),10000)),"") -> UNITAPAJÓS | E39: =IFERROR(INDEX(Carteira!$C:$C,MOD(SMALL(Carteira!$Q$5:$Q$204,1),10000)),"") -> PAULO NETTO | G39: =IFERROR(INDEX(Carteira!$N:$N,MOD(SMALL(Carteira!$Q$5:$Q$204,1),10000)),"") -> Bloqueado | I39: =IFERROR(INDEX(Carteira!$M:$M,MOD(SMALL(Carteira!$Q$5:$Q$204,1),10000)),"") -> — | K39: =IFERROR(INDEX(Carteira!$O:$O,MOD(SMALL(Carteira!$Q$5:$Q$204,1),10000)),"") -> Assinatura do contrato, pendente de decisão do cliente: casa de comando em alvenaria ou eletrocentro. Validação do cronograma pelo PM.
B40: =IFERROR(INDEX(Carteira!$A:$A,MOD(SMALL(Carteira!$Q$5:$Q$204,2),10000)),"") -> 24470001 | C40: =IFERROR(INDEX(Carteira!$B:$B,MOD(SMALL(Carteira!$Q$5:$Q$204,2),10000)),"") -> EBRASIL | E40: =IFERROR(INDEX(Carteira!$C:$C,MOD(SMALL(Carteira!$Q$5:$Q$204,2),10000)),"") -> MATHEUS | G40: =IFERROR(INDEX(Carteira!$N:$N,MOD(SMALL(Carteira!$Q$5:$Q$204,2),10000)),"") -> Atenção | I40: =IFERROR(INDEX(Carteira!$M:$M,MOD(SMALL(Carteira!$Q$5:$Q$204,2),10000)),"") -> 5 | K40: =IFERROR(INDEX(Carteira!$O:$O,MOD(SMALL(Carteira!$Q$5:$Q$204,2),10000)),"") -> Validação do cronograma pelo PM (último envio em 02/10/2026).
B41: =IFERROR(INDEX(Carteira!$A:$A,MOD(SMALL(Carteira!$Q$5:$Q$204,3),10000)),"") -> 33840002 | C41: =IFERROR(INDEX(Carteira!$B:$B,MOD(SMALL(Carteira!$Q$5:$Q$204,3),10000)),"") -> UNIMETAL | E41: =IFERROR(INDEX(Carteira!$C:$C,MOD(SMALL(Carteira!$Q$5:$Q$204,3),10000)),"") -> JEOVANNA | G41: =IFERROR(INDEX(Carteira!$N:$N,MOD(SMALL(Carteira!$Q$5:$Q$204,3),10000)),"") -> Atenção | I41: =IFERROR(INDEX(Carteira!$M:$M,MOD(SMALL(Carteira!$Q$5:$Q$204,3),10000)),"") -> 13 | K41: =IFERROR(INDEX(Carteira!$O:$O,MOD(SMALL(Carteira!$Q$5:$Q$204,3),10000)),"") -> Retorno da PM sobre a validação do cronograma (reenviado em 24/09/2026).
B42: =IFERROR(INDEX(Carteira!$A:$A,MOD(SMALL(Carteira!$Q$5:$Q$204,4),10000)),"") | C42: =IFERROR(INDEX(Carteira!$B:$B,MOD(SMALL(Carteira!$Q$5:$Q$204,4),10000)),"") | E42: =IFERROR(INDEX(Carteira!$C:$C,MOD(SMALL(Carteira!$Q$5:$Q$204,4),10000)),"") | G42: =IFERROR(INDEX(Carteira!$N:$N,MOD(SMALL(Carteira!$Q$5:$Q$204,4),10000)),"") | I42: =IFERROR(INDEX(Carteira!$M:$M,MOD(SMALL(Carteira!$Q$5:$Q$204,4),10000)),"") | K42: =IFERROR(INDEX(Carteira!$O:$O,MOD(SMALL(Carteira!$Q$5:$Q$204,4),10000)),"")
B43: =IFERROR(INDEX(Carteira!$A:$A,MOD(SMALL(Carteira!$Q$5:$Q$204,5),10000)),"") | C43: =IFERROR(INDEX(Carteira!$B:$B,MOD(SMALL(Carteira!$Q$5:$Q$204,5),10000)),"") | E43: =IFERROR(INDEX(Carteira!$C:$C,MOD(SMALL(Carteira!$Q$5:$Q$204,5),10000)),"") | G43: =IFERROR(INDEX(Carteira!$N:$N,MOD(SMALL(Carteira!$Q$5:$Q$204,5),10000)),"") | I43: =IFERROR(INDEX(Carteira!$M:$M,MOD(SMALL(Carteira!$Q$5:$Q$204,5),10000)),"") | K43: =IFERROR(INDEX(Carteira!$O:$O,MOD(SMALL(Carteira!$Q$5:$Q$204,5),10000)),"")
B44: =IFERROR(INDEX(Carteira!$A:$A,MOD(SMALL(Carteira!$Q$5:$Q$204,6),10000)),"") | C44: =IFERROR(INDEX(Carteira!$B:$B,MOD(SMALL(Carteira!$Q$5:$Q$204,6),10000)),"") | E44: =IFERROR(INDEX(Carteira!$C:$C,MOD(SMALL(Carteira!$Q$5:$Q$204,6),10000)),"") | G44: =IFERROR(INDEX(Carteira!$N:$N,MOD(SMALL(Carteira!$Q$5:$Q$204,6),10000)),"") | I44: =IFERROR(INDEX(Carteira!$M:$M,MOD(SMALL(Carteira!$Q$5:$Q$204,6),10000)),"") | K44: =IFERROR(INDEX(Carteira!$O:$O,MOD(SMALL(Carteira!$Q$5:$Q$204,6),10000)),"")
B45: =IFERROR(INDEX(Carteira!$A:$A,MOD(SMALL(Carteira!$Q$5:$Q$204,7),10000)),"") | C45: =IFERROR(INDEX(Carteira!$B:$B,MOD(SMALL(Carteira!$Q$5:$Q$204,7),10000)),"") | E45: =IFERROR(INDEX(Carteira!$C:$C,MOD(SMALL(Carteira!$Q$5:$Q$204,7),10000)),"") | G45: =IFERROR(INDEX(Carteira!$N:$N,MOD(SMALL(Carteira!$Q$5:$Q$204,7),10000)),"") | I45: =IFERROR(INDEX(Carteira!$M:$M,MOD(SMALL(Carteira!$Q$5:$Q$204,7),10000)),"") | K45: =IFERROR(INDEX(Carteira!$O:$O,MOD(SMALL(Carteira!$Q$5:$Q$204,7),10000)),"")
B46: =IFERROR(INDEX(Carteira!$A:$A,MOD(SMALL(Carteira!$Q$5:$Q$204,8),10000)),"") | C46: =IFERROR(INDEX(Carteira!$B:$B,MOD(SMALL(Carteira!$Q$5:$Q$204,8),10000)),"") | E46: =IFERROR(INDEX(Carteira!$C:$C,MOD(SMALL(Carteira!$Q$5:$Q$204,8),10000)),"") | G46: =IFERROR(INDEX(Carteira!$N:$N,MOD(SMALL(Carteira!$Q$5:$Q$204,8),10000)),"") | I46: =IFERROR(INDEX(Carteira!$M:$M,MOD(SMALL(Carteira!$Q$5:$Q$204,8),10000)),"") | K46: =IFERROR(INDEX(Carteira!$O:$O,MOD(SMALL(Carteira!$Q$5:$Q$204,8),10000)),"")
...

Sheet Carteira
A1: CARTEIRA DE OBRAS · PLANEJAMENTO · DEPARTAMENTO DE INSTALAÇÃO
A3: IDENTIFICAÇÃO | E3: PLANEJAMENTO | I3: MOBILIZAÇÃO | L3: ACOMPANHAMENTO | O3: REGISTRO
A4: Nº da obra | B4: Cliente | C4: PM | D4: Origem da demanda | E4: Fase | F4: Situação do cronograma | G4: Cadência de reunião | H4: Agenda da reunião | I4: Mobilização | J4: Situação da mobilização | K4: Dias até a mobilização | L4: Última interação | M4: Dias sem interação | N4: Status | O4: Pendência / bloqueio | P4: Resumo executivo | Q4: aux_painel
A5: 24480001 | B5: MOHAWK | C5: PAULO NETTO | D5: Distribuição do coordenador | E5: Projetos | F5: Validado pelo PM | G5: Não informada | I5: 46398 | J5: Definida | K5: =IF($A5="","",IF(ISNUMBER(I5),I5-TODAY(),"—")) -> 96 | L5: =IF($A5="","",IF(SUMPRODUCT(MAX((Histórico!$B$5:$B$1004=$A5)*Histórico!$A$5:$A$1004))=0,"—",SUMPRODUCT(MAX((Histórico!$B$5:$B$1004=$A5)*Histórico!$A$5:$A$1004)))) -> — | M5: =IF($A5="","",IF(ISNUMBER(L5),TODAY()-L5,"—")) -> — | N5: No prazo | O5: — | P5: Mobilização definida para 11/01/2027. Cronograma validado pelo PM. Obra em fase de projetos. | Q5: =IF(N5="Bloqueado",ROW(),IF(N5="Atenção",10000+ROW(),""))
A6: 24470001 | B6: EBRASIL | C6: MATHEUS | D6: Distribuição do coordenador | E6: Não informada | F6: Em ajuste com o PM | G6: Não informada | I6: 46398 | J6: Definida | K6: =IF($A6="","",IF(ISNUMBER(I6),I6-TODAY(),"—")) -> 96 | L6: =IF($A6="","",IF(SUMPRODUCT(MAX((Histórico!$B$5:$B$1004=$A6)*Histórico!$A$5:$A$1004))=0,"—",SUMPRODUCT(MAX((Histórico!$B$5:$B$1004=$A6)*Histórico!$A$5:$A$1004)))) -> 46297 | M6: =IF($A6="","",IF(ISNUMBER(L6),TODAY()-L6,"—")) -> 5 | N6: Atenção | O6: Validação do cronograma pelo PM (último envio em 02/10/2026). | P6: Mobilização definida para 11/01/2027. Cronograma ainda não validado; ajustes contínuos em conjunto com o PM. Último envio para validação em 02/10/2026. | Q6: =IF(N6="Bloqueado",ROW(),IF(N6="Atenção",10000+ROW(),"")) -> 10006
A7: 33900001 | B7: BIMBO | C7: JEOVANNA | D7: Distribuição do coordenador | E7: Projetos | F7: Em atualização periódica | G7: Semanal | H7: Segundas, 08:00 | J7: Não informada | K7: =IF($A7="","",IF(ISNUMBER(I7),I7-TODAY(),"—")) -> — | L7: =IF($A7="","",IF(SUMPRODUCT(MAX((Histórico!$B$5:$B$1004=$A7)*Histórico!$A$5:$A$1004))=0,"—",SUMPRODUCT(MAX((Histórico!$B$5:$B$1004=$A7)*Histórico!$A$5:$A$1004)))) -> — | M7: =IF($A7="","",IF(ISNUMBER(L7),TODAY()-L7,"—")) -> — | N7: No prazo | O7: — | P7: Reunião recorrente definida: toda segunda-feira, às 08:00. Obra em fase de projetos, dentro do prazo. | Q7: =IF(N7="Bloqueado",ROW(),IF(N7="Atenção",10000+ROW(),""))
A8: 33840002 | B8: UNIMETAL | C8: JEOVANNA | D8: Distribuição do coordenador | E8: Não informada | F8: Estruturado – aguardando validação | G8: Não informada | J8: Não informada | K8: =IF($A8="","",IF(ISNUMBER(I8),I8-TODAY(),"—")) -> — | L8: =IF($A8="","",IF(SUMPRODUCT(MAX((Histórico!$B$5:$B$1004=$A8)*Histórico!$A$5:$A$1004))=0,"—",SUMPRODUCT(MAX((Histórico!$B$5:$B$1004=$A8)*Histórico!$A$5:$A$1004)))) -> 46289 | M8: =IF($A8="","",IF(ISNUMBER(L8),TODAY()-L8,"—")) -> 13 | N8: Atenção | O8: Retorno da PM sobre a validação do cronograma (reenviado em 24/09/2026). | P8: Cronograma estruturado. No primeiro contato, a PM informou que ainda não poderia validá-lo, por não ter os prazos bem definidos. Em 24/09/2026, nova solicitação de validação, aceita pela PM; cronograma reenviado, sem retorno. | Q8: =IF(N8="Bloqueado",ROW(),IF(N8="Atenção",10000+ROW(),"")) -> 10008
A9: 18620005 | B9: MRN | C9: ERIKA | D9: Distribuição do coordenador | E9: Projetos | F9: Em atualização periódica | G9: Sem recorrência definida | J9: Não informada | K9: =IF($A9="","",IF(ISNUMBER(I9),I9-TODAY(),"—")) -> — | L9: =IF($A9="","",IF(SUMPRODUCT(MAX((Histórico!$B$5:$B$1004=$A9)*Histórico!$A$5:$A$1004))=0,"—",SUMPRODUCT(MAX((Histórico!$B$5:$B$1004=$A9)*Histórico!$A$5:$A$1004)))) -> 46288 | M9: =IF($A9="","",IF(ISNUMBER(L9),TODAY()-L9,"—")) -> 14 | N9: No prazo | O9: — | P9: Reuniões sem recorrência definida; quatro atualizações realizadas. Obra em fase de projetos, dentro do prazo. Última atualização em 05/10/2026. | Q9: =IF(N9="Bloqueado",ROW(),IF(N9="Atenção",10000+ROW(),""))
A10: 18620006 | B10: MRN | C10: ERIKA | D10: Distribuição do coordenador | E10: Projetos | F10: Em atualização periódica | G10: Sem recorrência definida | J10: Não informada | K10: =IF($A10="","",IF(ISNUMBER(I10),I10-TODAY(),"—")) -> — | L10: =IF($A10="","",IF(SUMPRODUCT(MAX((Histórico!$B$5:$B$1004=$A10)*Histórico!$A$5:$A$1004))=0,"—",SUMPRODUCT(MAX((Histórico!$B$5:$B$1004=$A10)*Histórico!$A$5:$A$1004)))) -> 46288 | M10: =IF($A10="","",IF(ISNUMBER(L10),TODAY()-L10,"—")) -> 14 | N10: No prazo | O10: — | P10: Reuniões sem recorrência definida; quatro atualizações realizadas. Obra em fase de projetos, dentro do prazo. Última atualização em 05/10/2026. | Q10: =IF(N10="Bloqueado",ROW(),IF(N10="Atenção",10000+ROW(),""))
A11: 24520001 | B11: UNITAPAJÓS | C11: PAULO NETTO | D11: Distribuição do coordenador | E11: Pré-contrato | F11: Estruturado – aguardando validação | G11: Sem recorrência definida | I11: Junho | J11: Estimada | K11: =IF($A11="","",IF(ISNUMBER(I11),I11-TODAY(),"—")) -> — | L11: =IF($A11="","",IF(SUMPRODUCT(MAX((Histórico!$B$5:$B$1004=$A11)*Histórico!$A$5:$A$1004))=0,"—",SUMPRODUCT(MAX((Histórico!$B$5:$B$1004=$A11)*Histórico!$A$5:$A$1004)))) -> — | M11: =IF($A11="","",IF(ISNUMBER(L11),TODAY()-L11,"—")) -> — | N11: Bloqueado | O11: Assinatura do contrato, pendente de decisão do cliente: casa de comando em alvenaria ou eletrocentro. Validação do cronograma pelo PM. | P11: Mobilização estimada para junho. Cronograma estruturado, ainda não validado pelo PM. Contrato não assinado: pendente decisão do cliente sobre a substituição da casa de comando em alvenaria por eletrocentro. | Q11: =IF(N11="Bloqueado",ROW(),IF(N11="Atenção",10000+ROW(),"")) -> 11
A12: 24440001 | B12: SENAI | C12: LAERÇO | D12: Distribuição do coordenador | E12: Não informada | F12: Validado e entregue | G12: Sem recorrência definida | J12: Não informada | K12: =IF($A12="","",IF(ISNUMBER(I12),I12-TODAY(),"—")) -> — | L12: =IF($A12="","",IF(SUMPRODUCT(MAX((Histórico!$B$5:$B$1004=$A12)*Histórico!$A$5:$A$1004))=0,"—",SUMPRODUCT(MAX((Histórico!$B$5:$B$1004=$A12)*Histórico!$A$5:$A$1004)))) -> 46283 | M12: =IF($A12="","",IF(ISNUMBER(L12),TODAY()-L12,"—")) -> 19 | N12: No prazo | O12: — | P12: Cronograma atualizado, validado pelo PM e entregue em 18/09/2026. Não há reunião recorrente definida. | Q12: =IF(N12="Bloqueado",ROW(),IF(N12="Atenção",10000+ROW(),""))
A13: 24080006 | B13: GAV | C13: ERIKA | D13: Distribuição do coordenador | E13: Projetos | F13: Em atualização periódica | G13: Sem recorrência definida | J13: Não informada | K13: =IF($A13="","",IF(ISNUMBER(I13),I13-TODAY(),"—")) -> — | L13: =IF($A13="","",IF(SUMPRODUCT(MAX((Histórico!$B$5:$B$1004=$A13)*Histórico!$A$5:$A$1004))=0,"—",SUMPRODUCT(MAX((Histórico!$B$5:$B$1004=$A13)*Histórico!$A$5:$A$1004)))) -> 46288 | M13: =IF($A13="","",IF(ISNUMBER(L13),TODAY()-L13,"—")) -> 14 | N13: No prazo | O13: — | P13: Reuniões sem recorrência definida; duas atualizações realizadas. Obra em fase de projetos, dentro do prazo. Última atualização em 23/09/2026. | Q13: =IF(N13="Bloqueado",ROW(),IF(N13="Atenção",10000+ROW(),""))
A14: 24080005 | B14: GAV | C14: ERIKA | D14: Distribuição do coordenador | E14: Projetos | F14: Em atualização periódica | G14: Sem recorrência definida | J14: Não informada | K14: =IF($A14="","",IF(ISNUMBER(I14),I14-TODAY(),"—")) -> — | L14: =IF($A14="","",IF(SUMPRODUCT(MAX((Histórico!$B$5:$B$1004=$A14)*Histórico!$A$5:$A$1004))=0,"—",SUMPRODUCT(MAX((Histórico!$B$5:$B$1004=$A14)*Histórico!$A$5:$A$1004)))) -> 46288 | M14: =IF($A14="","",IF(ISNUMBER(L14),TODAY()-L14,"—")) -> 14 | N14: No prazo | O14: — | P14: Reuniões sem recorrência definida; duas atualizações realizadas. Obra em fase de projetos, dentro do prazo. Última atualização em 23/09/2026. | Q14: =IF(N14="Bloqueado",ROW(),IF(N14="Atenção",10000+ROW(),""))
A15: 33960001 | B15: IPP NAVEGANTES | C15: LAERÇO | D15: Distribuição do coordenador | E15: Não informada | F15: Validado e entregue | G15: Sem recorrência definida | J15: Não informada | K15: =IF($A15="","",IF(ISNUMBER(I15),I15-TODAY(),"—")) -> — | L15: =IF($A15="","",IF(SUMPRODUCT(MAX((Histórico!$B$5:$B$1004=$A15)*Histórico!$A$5:$A$1004))=0,"—",SUMPRODUCT(MAX((Histórico!$B$5:$B$1004=$A15)*Histórico!$A$5:$A$1004)))) -> 46288 | M15: =IF($A15="","",IF(ISNUMBER(L15),TODAY()-L15,"—")) -> 14 | N15: No prazo | O15: — | P15: Cronograma atualizado, validado pelo PM e entregue em 23/09/2026. Não há reunião recorrente definida. | Q15: =IF(N15="Bloqueado",ROW(),IF(N15="Atenção",10000+ROW(),""))
A16: 30010034 | B16: CROWN | C16: LAURA | D16: Solicitação direta do PM | E16: Projetos | F16: Validado e entregue | G16: Não informada | J16: Não informada | K16: =IF($A16="","",IF(ISNUMBER(I16),I16-TODAY(),"—")) -> — | L16: =IF($A16="","",IF(SUMPRODUCT(MAX((Histórico!$B$5:$B$1004=$A16)*Histórico!$A$5:$A$1004))=0,"—",SUMPRODUCT(MAX((Histórico!$B$5:$B$1004=$A16)*Histórico!$A$5:$A$1004)))) -> — | M16: =IF($A16="","",IF(ISNUMBER(L16),TODAY()-L16,"—")) -> — | N16: Não avaliado | O16: — | P16: Cronograma não atribuído a mim pelo coordenador; a elaboração foi um pedido da Laura. Escopo: 1 painel e 1 invólucro. Não se sabe se haverá atualizações. | Q16: =IF(N16="Bloqueado",ROW(),IF(N16="Atenção",10000+ROW(),""))
K17: =IF($A17="","",IF(ISNUMBER(I17),I17-TODAY(),"—")) | L17: =IF($A17="","",IF(SUMPRODUCT(MAX((Histórico!$B$5:$B$1004=$A17)*Histórico!$A$5:$A$1004))=0,"—",SUMPRODUCT(MAX((Histórico!$B$5:$B$1004=$A17)*Histórico!$A$5:$A$1004)))) | M17: =IF($A17="","",IF(ISNUMBER(L17),TODAY()-L17,"—")) | Q17: =IF(N17="Bloqueado",ROW(),IF(N17="Atenção",10000+ROW(),""))
K18: =IF($A18="","",IF(ISNUMBER(I18),I18-TODAY(),"—")) | L18: =IF($A18="","",IF(SUMPRODUCT(MAX((Histórico!$B$5:$B$1004=$A18)*Histórico!$A$5:$A$1004))=0,"—",SUMPRODUCT(MAX((Histórico!$B$5:$B$1004=$A18)*Histórico!$A$5:$A$1004)))) | M18: =IF($A18="","",IF(ISNUMBER(L18),TODAY()-L18,"—")) | Q18: =IF(N18="Bloqueado",ROW(),IF(N18="Atenção",10000+ROW(),""))
K19: =IF($A19="","",IF(ISNUMBER(I19),I19-TODAY(),"—")) | L19: =IF($A19="","",IF(SUMPRODUCT(MAX((Histórico!$B$5:$B$1004=$A19)*Histórico!$A$5:$A$1004))=0,"—",SUMPRODUCT(MAX((Histórico!$B$5:$B$1004=$A19)*Histórico!$A$5:$A$1004)))) | M19: =IF($A19="","",IF(ISNUMBER(L19),TODAY()-L19,"—")) | Q19: =IF(N19="Bloqueado",ROW(),IF(N19="Atenção",10000+ROW(),""))
K20: =IF($A20="","",IF(ISNUMBER(I20),I20-TODAY(),"—")) | L20: =IF($A20="","",IF(SUMPRODUCT(MAX((Histórico!$B$5:$B$1004=$A20)*Histórico!$A$5:$A$1004))=0,"—",SUMPRODUCT(MAX((Histórico!$B$5:$B$1004=$A20)*Histórico!$A$5:$A$1004)))) | M20: =IF($A20="","",IF(ISNUMBER(L20),TODAY()-L20,"—")) | Q20: =IF(N20="Bloqueado",ROW(),IF(N20="Atenção",10000+ROW(),""))
K21: =IF($A21="","",IF(ISNUMBER(I21),I21-TODAY(),"—")) | L21: =IF($A21="","",IF(SUMPRODUCT(MAX((Histórico!$B$5:$B$1004=$A21)*Histórico!$A$5:$A$1004))=0,"—",SUMPRODUCT(MAX((Histórico!$B$5:$B$1004=$A21)*Histórico!$A$5:$A$1004)))) | M21: =IF($A21="","",IF(ISNUMBER(L21),TODAY()-L21,"—")) | Q21: =IF(N21="Bloqueado",ROW(),IF(N21="Atenção",10000+ROW(),""))
K22: =IF($A22="","",IF(ISNUMBER(I22),I22-TODAY(),"—")) | L22: =IF($A22="","",IF(SUMPRODUCT(MAX((Histórico!$B$5:$B$1004=$A22)*Histórico!$A$5:$A$1004))=0,"—",SUMPRODUCT(MAX((Histórico!$B$5:$B$1004=$A22)*Histórico!$A$5:$A$1004)))) | M22: =IF($A22="","",IF(ISNUMBER(L22),TODAY()-L22,"—")) | Q22: =IF(N22="Bloqueado",ROW(),IF(N22="Atenção",10000+ROW(),""))
K23: =IF($A23="","",IF(ISNUMBER(I23),I23-TODAY(),"—")) | L23: =IF($A23="","",IF(SUMPRODUCT(MAX((Histórico!$B$5:$B$1004=$A23)*Histórico!$A$5:$A$1004))=0,"—",SUMPRODUCT(MAX((Histórico!$B$5:$B$1004=$A23)*Histórico!$A$5:$A$1004)))) | M23: =IF($A23="","",IF(ISNUMBER(L23),TODAY()-L23,"—")) | Q23: =IF(N23="Bloqueado",ROW(),IF(N23="Atenção",10000+ROW(),""))
K24: =IF($A24="","",IF(ISNUMBER(I24),I24-TODAY(),"—")) | L24: =IF($A24="","",IF(SUMPRODUCT(MAX((Histórico!$B$5:$B$1004=$A24)*Histórico!$A$5:$A$1004))=0,"—",SUMPRODUCT(MAX((Histórico!$B$5:$B$1004=$A24)*Histórico!$A$5:$A$1004)))) | M24: =IF($A24="","",IF(ISNUMBER(L24),TODAY()-L24,"—")) | Q24: =IF(N24="Bloqueado",ROW(),IF(N24="Atenção",10000+ROW(),""))
K25: =IF($A25="","",IF(ISNUMBER(I25),I25-TODAY(),"—")) | L25: =IF($A25="","",IF(SUMPRODUCT(MAX((Histórico!$B$5:$B$1004=$A25)*Histórico!$A$5:$A$1004))=0,"—",SUMPRODUCT(MAX((Histórico!$B$5:$B$1004=$A25)*Histórico!$A$5:$A$1004)))) | M25: =IF($A25="","",IF(ISNUMBER(L25),TODAY()-L25,"—")) | Q25: =IF(N25="Bloqueado",ROW(),IF(N25="Atenção",10000+ROW(),""))
K26: =IF($A26="","",IF(ISNUMBER(I26),I26-TODAY(),"—")) | L26: =IF($A26="","",IF(SUMPRODUCT(MAX((Histórico!$B$5:$B$1004=$A26)*Histórico!$A$5:$A$1004))=0,"—",SUMPRODUCT(MAX((Histórico!$B$5:$B$1004=$A26)*Histórico!$A$5:$A$1004)))) | M26: =IF($A26="","",IF(ISNUMBER(L26),TODAY()-L26,"—")) | Q26: =IF(N26="Bloqueado",ROW(),IF(N26="Atenção",10000+ROW(),""))
K27: =IF($A27="","",IF(ISNUMBER(I27),I27-TODAY(),"—")) | L27: =IF($A27="","",IF(SUMPRODUCT(MAX((Histórico!$B$5:$B$1004=$A27)*Histórico!$A$5:$A$1004))=0,"—",SUMPRODUCT(MAX((Histórico!$B$5:$B$1004=$A27)*Histórico!$A$5:$A$1004)))) | M27: =IF($A27="","",IF(ISNUMBER(L27),TODAY()-L27,"—")) | Q27: =IF(N27="Bloqueado",ROW(),IF(N27="Atenção",10000+ROW(),""))
K28: =IF($A28="","",IF(ISNUMBER(I28),I28-TODAY(),"—")) | L28: =IF($A28="","",IF(SUMPRODUCT(MAX((Histórico!$B$5:$B$1004=$A28)*Histórico!$A$5:$A$1004))=0,"—",SUMPRODUCT(MAX((Histórico!$B$5:$B$1004=$A28)*Histórico!$A$5:$A$1004)))) | M28: =IF($A28="","",IF(ISNUMBER(L28),TODAY()-L28,"—")) | Q28: =IF(N28="Bloqueado",ROW(),IF(N28="Atenção",10000+ROW(),""))
... K204: =IF($A204="","",IF(ISNUMBER(I204),I204-TODAY(),"—")) | L204: =IF($A204="","",IF(SUMPRODUCT(MAX((Histórico!$B$5:$B$1004=$A204)*Histórico!$A$5:$A$1004))=0,"—",SUMPRODUCT(MAX((Histórico!$B$5:$B$1004=$A204)*Histórico!$A$5:$A$1004)))) | M204: =IF($A204="","",IF(ISNUMBER(L204),TODAY()-L204,"—")) | Q204: =IF(N204="Bloqueado",ROW(),IF(N204="Atenção",10000+ROW(),""))

Sheet Planilha1
A1: ID | B1: Pacote | C1: Atividade que recebe peso | D1: Duração | E1: Pontos | H1: ID | I1: Pacote | J1: Atividade | K1: Duração | L1: Pontos
A2: 9 | B2: QGBT-02-BM | C2: Elaboração de projeto | D2: 3,0 d | E2: 6.38 | H2: 122 | I2: Infraestrutura/Elétrica | J2: Montagem de infraestrutura | K2: 3 d | L2: 33.33
A3: 11 | B3: QGBT-02-BM | C3: Análise e comentários ORIZON | D3: 1,0 d | E3: 2.13 | H3: 123 | I3: Infraestrutura/Elétrica | J3: Lançamento de cabos | K3: 2 d | L3: 22.22
A4: 12 | B4: QGBT-02-BM | C4: Reemissão de projetos | D4: 2,0 d | E4: 4.26 | H4: 124 | I4: Infraestrutura/Elétrica | J4: Confecção de terminais | K4: 1 d | L4: 11.11
A5: 15 | B5: QGBT-02-BM | C5: Metalúrgica | D5: 7,0 d | E5: 14.89 | H5: 126 | I5: Instalação | J5: PMT 13,8 kV | K5: 3 d | L5: 33.33
A6: 16 | B6: QGBT-02-BM | C6: Montagem | D6: 4,0 d | E6: 8.51 | H6: 127 | I6: Instalação | J6: QGBT-01-BM | K6: 4 d | L6: 44.44
A7: 17 | B7: QGBT-02-BM | C7: TAF e testes internos | D7: 3,0 d | E7: 6.38 | H7: 128 | I7: Instalação | J7: Busway 3200 A | K7: 3 d | L7: 33.33
A8: 18 | B8: QGBT-02-BM | C8: Embalagem | D8: 0,5 d | E8: 1.06 | H8: 129 | I8: Instalação | J8: QGBT-02-BM | K8: 1 d | L8: 11.11
A9: 19 | B9: QGBT-02-BM | C9: Expedição | D9: 0,5 d | E9: 1.06 | H9: 130 | I9: Instalação | J9: QUPS-01-BM | K9: 1 d | L9: 11.11
A10: 20 | B10: QGBT-02-BM | C10: Transporte | D10: 2,0 d | E10: 4.26 | H10: 131 | I10: Instalação | J10: QGBT-04-BM | K10: 1 d | L10: 11.11
B11: Subtotal QGBT-02-BM | D11: 23 d | E11: 48.93 | H11: 132 | I11: Instalação | J11: TF-02-BM | K11: 1 d | L11: 11.11
A12: 24 | B12: QUPS-01-BM | C12: Elaboração de projeto | D12: 4,0 d | E12: 8.51 | H12: 133 | I12: Instalação | J12: TF-03-BM | K12: 1 d | L12: 11.11
A13: 26 | B13: QUPS-01-BM | C13: Análise e comentários ORIZON | D13: 1,0 d | E13: 2.13 | H13: 134 | I13: Instalação | J13: UPS-01-BM | K13: 1 d | L13: 11.11
A14: 27 | B14: QUPS-01-BM | C14: Reemissão de projetos | D14: 2,0 d | E14: 4.26 | H14: 135 | I14: Instalação | J14: Transformador de força | K14: 1 d | L14: 11.11
A15: 30 | B15: QUPS-01-BM | C15: Metalúrgica | D15: 6,0 d | E15: 12.77 | H15: 137 | I15: Comissionamento | J15: Comissionamento | K15: 3 d | L15: 33.33
A16: 31 | B16: QUPS-01-BM | C16: Montagem | D16: 4,0 d | E16: 8.51 | H16: 138 | I16: Start-up | J16: Start-up | K16: 1 d | L16: 11,14*
A17: 32 | B17: QUPS-01-BM | C17: TAF | D17: 3,0 d | E17: 6.38 | I17: TOTAL SERVIÇOS | K17: 27 d | L17: 300
A18: 33 | B18: QUPS-01-BM | C18: Embalagem | D18: 0,5 d | E18: 1.06
A19: 34 | B19: QUPS-01-BM | C19: Expedição | D19: 0,5 d | E19: 1.06
A20: 35 | B20: QUPS-01-BM | C20: Transporte | D20: 2,0 d | E20: 4.26
B21: Subtotal QUPS-01-BM | D21: 23 d | E21: 48.94
A22: 39 | B22: QGBT-04-BM | C22: Elaboração de projeto | D22: 4,0 d | E22: 8.51
A23: 41 | B23: QGBT-04-BM | C23: Análise e comentários ORIZON | D23: 1,0 d | E23: 2.13
A24: 42 | B24: QGBT-04-BM | C24: Reemissão de projetos | D24: 2,0 d | E24: 4.26
A25: 45 | B25: QGBT-04-BM | C25: Metalúrgica | D25: 6,0 d | E25: 12.77
A26: 46 | B26: QGBT-04-BM | C26: Montagem | D26: 4,0 d | E26: 8.51
A27: 47 | B27: QGBT-04-BM | C27: TAF | D27: 3,0 d | E27: 6.38
A28: 48 | B28: QGBT-04-BM | C28: Embalagem | D28: 0,5 d | E28: 1.06
A29: 49 | B29: QGBT-04-BM | C29: Expedição | D29: 0,5 d | E29: 1.06
A30: 50 | B30: QGBT-04-BM | C30: Transporte | D30: 2,0 d | E30: 4.26
B31: Subtotal QGBT-04-BM | D31: 23 d | E31: 48.94
A32: 54 | B32: QGBT-01-BM | C32: Elaboração de projeto | D32: 4,0 d | E32: 8.51
A33: 56 | B33: QGBT-01-BM | C33: Análise e comentários ORIZON | D33: 1,0 d | E33: 2.13
A34: 57 | B34: QGBT-01-BM | C34: Reemissão de projetos | D34: 2,0 d | E34: 4.26
A35: 60 | B35: QGBT-01-BM | C35: Metalúrgica | D35: 7,0 d | E35: 14.89
A36: 61 | B36: QGBT-01-BM | C36: Montagem | D36: 4,0 d | E36: 8.51
A37: 62 | B37: QGBT-01-BM | C37: TAF | D37: 3,0 d | E37: 6.38
A38: 63 | B38: QGBT-01-BM | C38: Embalagem | D38: 0,5 d | E38: 1.06
A39: 64 | B39: QGBT-01-BM | C39: Expedição | D39: 0,5 d | E39: 1.06
A40: 65 | B40: QGBT-01-BM | C40: Transporte | D40: 2,0 d | E40: 4.26
...

Sheet Histórico
A1: HISTÓRICO DE EVENTOS · registro cronológico de tudo o que acontece em cada obra
A2: Lance cada novo evento na primeira linha vazia · A coluna 'Cliente' é preenchida automaticamente · A data mais recente de cada obra alimenta a coluna 'Última interação' da Carteira
A3: Eventos sem data no registro original foram mantidos com a data em branco (não contam para 'Última interação').
A4: Data do evento | B4: Nº da obra | C4: Cliente | D4: Tipo de evento | E4: Descrição | F4: Registrado por
B5: 24480001 | C5: =IF(B5="","",IFERROR(INDEX(Carteira!$B$5:$B$204,MATCH(B5,Carteira!$A$5:$A$204,0)),"Obra não cadastrada")) -> MOHAWK | D5: Definição de mobilização | E5: Mobilização definida para 11/01/2027. | F5: OSVALDO
B6: 24480001 | C6: =IF(B6="","",IFERROR(INDEX(Carteira!$B$5:$B$204,MATCH(B6,Carteira!$A$5:$A$204,0)),"Obra não cadastrada")) -> MOHAWK | D6: Validação do PM | E6: Cronograma validado pelo PM. | F6: OSVALDO
B7: 24480001 | C7: =IF(B7="","",IFERROR(INDEX(Carteira!$B$5:$B$204,MATCH(B7,Carteira!$A$5:$A$204,0)),"Obra não cadastrada")) -> MOHAWK | D7: Linha de base | E7: Obra em fase de projetos. | F7: OSVALDO
B8: 24470001 | C8: =IF(B8="","",IFERROR(INDEX(Carteira!$B$5:$B$204,MATCH(B8,Carteira!$A$5:$A$204,0)),"Obra não cadastrada")) -> EBRASIL | D8: Definição de mobilização | E8: Mobilização definida para 11/01/2027. | F8: OSVALDO
A9: 46297 | B9: 24470001 | C9: =IF(B9="","",IFERROR(INDEX(Carteira!$B$5:$B$204,MATCH(B9,Carteira!$A$5:$A$204,0)),"Obra não cadastrada")) -> EBRASIL | D9: Envio para validação | E9: Cronograma enviado ao PM para validação, após ajustes contínuos em conjunto. | F9: OSVALDO
B10: 33900001 | C10: =IF(B10="","",IFERROR(INDEX(Carteira!$B$5:$B$204,MATCH(B10,Carteira!$A$5:$A$204,0)),"Obra não cadastrada")) -> BIMBO | D10: Reunião | E10: Reunião recorrente definida: toda segunda-feira, às 08:00. | F10: OSVALDO
B11: 33900001 | C11: =IF(B11="","",IFERROR(INDEX(Carteira!$B$5:$B$204,MATCH(B11,Carteira!$A$5:$A$204,0)),"Obra não cadastrada")) -> BIMBO | D11: Linha de base | E11: Obra em fase de projetos, dentro do prazo. | F11: OSVALDO
B12: 33840002 | C12: =IF(B12="","",IFERROR(INDEX(Carteira!$B$5:$B$204,MATCH(B12,Carteira!$A$5:$A$204,0)),"Obra não cadastrada")) -> UNIMETAL | D12: Retorno do PM | E12: Primeiro contato: a PM informou que ainda não poderia validar o cronograma, por não ter os prazos bem definidos. | F12: OSVALDO
A13: 46289 | B13: 33840002 | C13: =IF(B13="","",IFERROR(INDEX(Carteira!$B$5:$B$204,MATCH(B13,Carteira!$A$5:$A$204,0)),"Obra não cadastrada")) -> UNIMETAL | D13: Envio para validação | E13: Nova solicitação de validação, aceita pela PM. Cronograma reenviado; sem retorno. | F13: OSVALDO
A14: 46288 | B14: 18620005 | C14: =IF(B14="","",IFERROR(INDEX(Carteira!$B$5:$B$204,MATCH(B14,Carteira!$A$5:$A$204,0)),"Obra não cadastrada")) -> MRN | D14: Atualização de cronograma | E14: Terceira atualização do cronograma. Obra em fase de projetos, dentro do prazo. | F14: OSVALDO
A15: 46288 | B15: 18620006 | C15: =IF(B15="","",IFERROR(INDEX(Carteira!$B$5:$B$204,MATCH(B15,Carteira!$A$5:$A$204,0)),"Obra não cadastrada")) -> MRN | D15: Atualização de cronograma | E15: Terceira atualização do cronograma. Obra em fase de projetos, dentro do prazo. | F15: OSVALDO
B16: 24520001 | C16: =IF(B16="","",IFERROR(INDEX(Carteira!$B$5:$B$204,MATCH(B16,Carteira!$A$5:$A$204,0)),"Obra não cadastrada")) -> UNITAPAJÓS | D16: Definição de mobilização | E16: Mobilização estimada para junho. | F16: OSVALDO
B17: 24520001 | C17: =IF(B17="","",IFERROR(INDEX(Carteira!$B$5:$B$204,MATCH(B17,Carteira!$A$5:$A$204,0)),"Obra não cadastrada")) -> UNITAPAJÓS | D17: Linha de base | E17: Cronograma estruturado, ainda não validado pelo PM. | F17: OSVALDO
B18: 24520001 | C18: =IF(B18="","",IFERROR(INDEX(Carteira!$B$5:$B$204,MATCH(B18,Carteira!$A$5:$A$204,0)),"Obra não cadastrada")) -> UNITAPAJÓS | D18: Pendência / bloqueio | E18: Contrato não assinado: pendente decisão do cliente sobre a substituição da casa de comando em alvenaria por eletrocentro. | F18: OSVALDO
A19: 46283 | B19: 24440001 | C19: =IF(B19="","",IFERROR(INDEX(Carteira!$B$5:$B$204,MATCH(B19,Carteira!$A$5:$A$204,0)),"Obra não cadastrada")) -> SENAI | D19: Entrega de cronograma | E19: Cronograma atualizado e validado pelo PM entregue. | F19: OSVALDO
A20: 46288 | B20: 24080006 | C20: =IF(B20="","",IFERROR(INDEX(Carteira!$B$5:$B$204,MATCH(B20,Carteira!$A$5:$A$204,0)),"Obra não cadastrada")) -> GAV | D20: Atualização de cronograma | E20: Segunda atualização do cronograma. Obra em fase de projetos, dentro do prazo. | F20: OSVALDO
A21: 46288 | B21: 24080005 | C21: =IF(B21="","",IFERROR(INDEX(Carteira!$B$5:$B$204,MATCH(B21,Carteira!$A$5:$A$204,0)),"Obra não cadastrada")) -> GAV | D21: Atualização de cronograma | E21: Segunda atualização do cronograma. Obra em fase de projetos, dentro do prazo. | F21: OSVALDO
A22: 46288 | B22: 33960001 | C22: =IF(B22="","",IFERROR(INDEX(Carteira!$B$5:$B$204,MATCH(B22,Carteira!$A$5:$A$204,0)),"Obra não cadastrada")) -> IPP NAVEGANTES | D22: Entrega de cronograma | E22: Cronograma atualizado e validado pelo PM entregue. | F22: OSVALDO
B23: 30010034 | C23: =IF(B23="","",IFERROR(INDEX(Carteira!$B$5:$B$204,MATCH(B23,Carteira!$A$5:$A$204,0)),"Obra não cadastrada")) -> CROWN | D23: Solicitação de demanda | E23: Cronograma não atribuído a mim pelo coordenador; a elaboração foi um pedido da Laura. Escopo: 1 painel e 1 invólucro. | F23: OSVALDO
C24: =IF(B24="","",IFERROR(INDEX(Carteira!$B$5:$B$204,MATCH(B24,Carteira!$A$5:$A$204,0)),"Obra não cadastrada"))
C25: =IF(B25="","",IFERROR(INDEX(Carteira!$B$5:$B$204,MATCH(B25,Carteira!$A$5:$A$204,0)),"Obra não cadastrada"))
C26: =IF(B26="","",IFERROR(INDEX(Carteira!$B$5:$B$204,MATCH(B26,Carteira!$A$5:$A$204,0)),"Obra não cadastrada"))
C27: =IF(B27="","",IFERROR(INDEX(Carteira!$B$5:$B$204,MATCH(B27,Carteira!$A$5:$A$204,0)),"Obra não cadastrada"))
C28: =IF(B28="","",IFERROR(INDEX(Carteira!$B$5:$B$204,MATCH(B28,Carteira!$A$5:$A$204,0)),"Obra não cadastrada"))
C29: =IF(B29="","",IFERROR(INDEX(Carteira!$B$5:$B$204,MATCH(B29,Carteira!$A$5:$A$204,0)),"Obra não cadastrada"))
C30: =IF(B30="","",IFERROR(INDEX(Carteira!$B$5:$B$204,MATCH(B30,Carteira!$A$5:$A$204,0)),"Obra não cadastrada"))
C31: =IF(B31="","",IFERROR(INDEX(Carteira!$B$5:$B$204,MATCH(B31,Carteira!$A$5:$A$204,0)),"Obra não cadastrada"))
C32: =IF(B32="","",IFERROR(INDEX(Carteira!$B$5:$B$204,MATCH(B32,Carteira!$A$5:$A$204,0)),"Obra não cadastrada"))
C33: =IF(B33="","",IFERROR(INDEX(Carteira!$B$5:$B$204,MATCH(B33,Carteira!$A$5:$A$204,0)),"Obra não cadastrada"))
C34: =IF(B34="","",IFERROR(INDEX(Carteira!$B$5:$B$204,MATCH(B34,Carteira!$A$5:$A$204,0)),"Obra não cadastrada"))
C35: =IF(B35="","",IFERROR(INDEX(Carteira!$B$5:$B$204,MATCH(B35,Carteira!$A$5:$A$204,0)),"Obra não cadastrada"))
... C1004: =IF(B1004="","",IFERROR(INDEX(Carteira!$B$5:$B$204,MATCH(B1004,Carteira!$A$5:$A$204,0)),"Obra não cadastrada"))

Sheet Listas
A1: CADASTROS — valores das listas suspensas (inclua novos valores na primeira célula vazia da coluna, sem deixar linhas em branco)
A2: Fase | B2: Situação do cronograma | C2: Cadência de reunião | D2: Situação da mobilização | E2: Status | F2: Origem da demanda | G2: Tipo de evento | H2: PM | J2: Parâmetros de alerta | K2: Valor
A3: Pré-contrato | B3: Em elaboração | C3: Semanal | D3: Definida | E3: No prazo | F3: Distribuição do coordenador | G3: Linha de base | H3: PAULO NETTO | J3: Dias sem interação — alerta (amarelo) | K3: 7
A4: Projetos | B4: Estruturado – aguardando validação | C4: Quinzenal | D4: Estimada | E4: Atenção | F4: Solicitação direta do PM | G4: Definição de mobilização | H4: MATHEUS | J4: Dias sem interação — crítico (vermelho) | K4: 14
A5: Fabricação | B5: Em ajuste com o PM | C5: Mensal | D5: Não informada | E5: Bloqueado | G5: Envio para validação | H5: JEOVANNA | J5: Dias até a mobilização — alerta (amarelo) | K5: 60
A6: Mobilização | B6: Validado pelo PM | C6: Sem recorrência definida | E6: Não avaliado | G6: Retorno do PM | H6: ERIKA | J6: Dias até a mobilização — crítico (vermelho) | K6: 30
A7: Execução em campo | B7: Validado e entregue | C7: Não informada | G7: Validação do PM | H7: LAERÇO
A8: Comissionamento | B8: Em atualização periódica | E8: (valores fixos: usados nos indicadores) | G8: Entrega de cronograma | H8: LAURA | J8: Altere os valores em amarelo para recalibrar os alertas do Painel e da Carteira.
A9: Encerrada | B9: Não informada | G9: Atualização de cronograma
A10: Não informada | G10: Reunião
G11: Pendência / bloqueio
G12: Solicitação de demanda
G13: Outro

Sheet Guia
B1: GUIA DE USO · como manter e expandir esta planilha
B3: Objetivo
B4: Para que serve | C4: Acompanhar a rotina de planejamento do Departamento de Instalação: em que etapa está o cronograma de cada obra, como está o ciclo de validação com os PMs, quais obras exigem ação e qual a data da última interação registrada.
B6: Estrutura da planilha
B7: Painel | C7: Visão gerencial para a reunião com a coordenação. 100% automática: não digite nada nesta aba.
B8: Carteira | C8: Estado atual de cada obra (uma linha por obra). É aqui que se atualizam fase, situação do cronograma, status, pendência e resumo.
B9: Histórico | C9: Registro cronológico de eventos (envios, validações, reuniões, entregas, pendências). Só se acrescentam linhas; nada é apagado.
B10: Listas | C10: Cadastro dos valores das listas suspensas (fases, situações, PMs, tipos de evento) e parâmetros dos alertas.
B11: Guia | C11: Este manual.
B13: Rotina semanal de atualização
B14: 1. Registrar eventos | C14: Na aba Histórico, lance cada acontecimento da semana na primeira linha vazia: data, nº da obra (lista), tipo de evento (lista) e descrição curta.
B15: 2. Atualizar a Carteira | C15: Para cada obra que teve evento, revise as colunas Fase, Situação do cronograma, Cadência de reunião, Mobilização e Status.
B16: 3. Revisar o registro | C16: Atualize 'Pendência / bloqueio' (o que falta e de quem depende) e 'Resumo executivo' (situação atual em até três frases).
B17: 4. Conferir o Painel | C17: Antes da reunião, confira os indicadores, o fluxo por etapa e a seção 'Pontos de atenção'.
B19: Como expandir
B20: Nova obra | C20: Preencha a primeira linha vazia da Carteira. As colunas cinza (dias até a mobilização, última interação, dias sem interação) já contêm as fórmulas até a linha 204. O nº da obra não pode se repetir.
B21: Novo PM, fase, situação ou tipo de evento | C21: Na aba Listas, digite o novo valor na primeira célula vazia da coluna correspondente, sem deixar linhas em branco. Ele passa a aparecer na lista suspensa e, no caso de PM, na tabela do Painel.
B22: Nova etapa do fluxo | C22: As seis etapas do Painel leem as células B3 a B8 da aba Listas; 'Não informada' fica em B9. Para renomear uma etapa, altere o texto na aba Listas: o Painel e as contagens se ajustam. Para criar uma sétima etapa, insira-a na lista e acrescente um bloco no Painel.
B23: Recalibrar alertas | C23: Na aba Listas, altere os parâmetros em amarelo: dias sem interação (alerta e crítico) e dias até a mobilização (alerta e crítico).
B24: Valores fixos | C24: Os quatro status (No prazo, Atenção, Bloqueado, Não avaliado) alimentam as fórmulas dos indicadores. Não os renomeie.
B26: Critérios de status
B27: No prazo | C27: Cronograma validado, entregue ou em atualização regular, sem pendência fora do controle do planejamento.
B28: Atenção | C28: Cronograma sem validação com mobilização definida, ou solicitação ao PM sem retorno.
B29: Bloqueado | C29: O avanço depende de decisão contratual ou do cliente.
B30: Não avaliado | C30: Informação insuficiente para classificar a obra.
B32: Dicionário de campos — aba Carteira
B33: Nº da obra | C33: Número da obra no sistema da Volga. Único por linha.
B34: Cliente | C34: Nome do cliente, em maiúsculas.
B35: PM | C35: Gerente do projeto responsável pela validação do cronograma (lista; aceita nome novo com aviso).
B36: Origem da demanda | C36: Se a obra veio da distribuição do coordenador ou de solicitação direta do PM.
B37: Fase | C37: Fase atual da obra. Use 'Não informada' quando o dado ainda não for conhecido.
B38: Situação do cronograma | C38: Etapa do cronograma no fluxo de planejamento (alimenta o fluxo do Painel).
B39: Cadência de reunião | C39: Periodicidade das reuniões de acompanhamento com o PM.
B40: Agenda da reunião | C40: Dia e horário da reunião recorrente, quando houver.
B41: Mobilização | C41: Data de mobilização (dd/mm/aaaa). Se só houver estimativa sem data, escreva o texto (ex.: 'Junho').
B42: Situação da mobilização | C42: Definida, Estimada ou Não informada.
B43: Dias até a mobilização | C43: Automático. Fica amarelo/vermelho conforme os parâmetros.
B44: Última interação | C44: Automático: data mais recente lançada no Histórico para a obra.
... B48: Resumo executivo | C48: Situação atual em frases curtas, começando pelo fato e com datas no formato dd/mm/aaaa.
B50: Convenções de redação
...
